Workbook

Sheet Resumen
A1: Resumen financiero — Plan de Asistencia Legal a Cooperativas de Transporte
A2: Cambie el escenario en Supuestos!B4. Todos los valores se recalculan.
A4: Rentabilidad del proyecto (36 meses, después de impuestos)
A5: Escenario activo | B5: =INDEX(Supuestos!B6:D6,1,Supuestos!B4)
A6: TIR mensual | B6: =IFERROR(IRR('Flujo 36 meses'!B20:AL20),"No hay TIR (no recupera)")
A7: TIR anual equivalente | B7: =IFERROR((1+B6)^12-1,"No hay TIR") | C7: comparar contra la tasa de descuento
A8: VAN al costo de oportunidad | B8: ='Flujo 36 meses'!B20+NPV((1+Supuestos!$E$48)^(1/12)-1,'Flujo 36 meses'!C20:AL20) | C8: > 0 significa que crea valor
A9: Mes de recupero de la inversión | B9: =IF(COUNT('Flujo 36 meses'!C22:AL22)=0,"No recupera en 36 meses",MIN('Flujo 36 meses'!C22:AL22))
A10: Peor caja acumulada (capital de trabajo necesario) | B10: =MIN('Flujo 36 meses'!B21:AL21) | C10: plata que hay que tener disponible antes de que el plan se pague solo
A11: Flujo acumulado al mes 36 | B11: ='Flujo 36 meses'!AL21
A12: Cooperativas activas al mes 36 | B12: ='Flujo 36 meses'!AL4
A13: Ingreso cobrado mes 36 | B13: ='Flujo 36 meses'!AL8
A14: Margen operativo mes 36 | B14: =IFERROR('Flujo 36 meses'!AL18/B13,0)
A16: Punto de equilibrio (régimen estable, antes de impuestos)
A17: Ingreso cobrado por cooperativa (mensual) | B17: =(Supuestos!$E$9+Supuestos!$E$8*Supuestos!$E$10)*(1-Supuestos!$E$12*Supuestos!$E$13)*(1-Supuestos!$E$14)
A18: Horas de abogado por cooperativa (mensual) | B18: =Supuestos!$E$24+Supuestos!$E$8*(Supuestos!$E$19*Supuestos!$E$25+Supuestos!$E$20*Supuestos!$E$26+Supuestos!$E$21*Supuestos!$E$27+Supuestos!$E$22*Supuestos!$E$28)/12
A19: Costo por hora de abogado | B19: =Supuestos!$E$34/Supuestos!$E$35
A20: Costo de abogado por cooperativa (mensual) | B20: =B18*B19
A21: Gastos directos por cooperativa (mensual) | B21: =Supuestos!$E$8*(Supuestos!$E$19*Supuestos!$E$30+Supuestos!$E$20*Supuestos!$E$31+Supuestos!$E$21*Supuestos!$E$32)/12
A22: Contribución por cooperativa (mensual) | B22: =B17-B20-B21 | C22: lo que deja cada cooperativa para cubrir fijos
A23: Costos fijos (sin abogados) | B23: =Supuestos!$E$37+Supuestos!$E$38+Supuestos!$E$39+Supuestos!$E$40+Supuestos!$E$41+Supuestos!$E$42+Supuestos!$E$43+Supuestos!$E$44
A24: PUNTO DE EQUILIBRIO — cooperativas | B24: =IF(B22<=0,"Nunca: cada cooperativa pierde plata",B23/B22)
A25: PUNTO DE EQUILIBRIO — buses | B25: =IF(B22<=0,"Nunca",B24*Supuestos!$E$8)
A26: Siniestralidad máxima tolerable (multiplicador sobre la supuesta) | B26: =IFERROR((B17-B23/MAX(1,Supuestos!$E$17/2)-Supuestos!$E$24*B19)/(B18*B19-Supuestos!$E$24*B19+B21),0) | C26: con la mitad del techo de cooperativas: si los siniestros se multiplican por más que esto, se pierde dinero
A27: Cuota mínima por bus para equilibrio con 5 cooperativas | B27: =((B23/5+B20+B21)/((1-Supuestos!$E$12*Supuestos!$E$13)*(1-Supuestos!$E$14))-Supuestos!$E$9)/Supuestos!$E$8 | C27: USD/bus/mes
A29: Sensibilidad: punto de equilibrio (cooperativas) según cuota por bus y siniestralidad
A30: Cuota por bus (USD/mes) ↓ · multiplicador de siniestralidad → | B30: 0.5 | C30: 1 | D30: 1.5 | E30: 2 | F30: 3
A31: 10 | B31: =IF((Supuestos!$E$9+Supuestos!$E$8*$A31)*(1-Supuestos!$E$12*Supuestos!$E$13)*(1-Supuestos!$E$14)-(Supuestos!$E$24*$B$19+B$30*(Supuestos!$E$8*(Supuestos!$E$19*Supuestos!$E$25+Supuestos!$E$20*Supuestos!$E$26+Supuestos!$E$21*Supuestos!$E$27+Supuestos!$E$22*Supuestos!$E$28)/12*$B$19+$B$21))<=0,"Pierde",$B$23/((Supuestos!$E$9+Supuestos!$E$8*$A31)*(1-Supuestos!$E$12*Supuestos!$E$13)*(1-Supuestos!$E$14)-(Supuestos!$E$24*$B$19+B$30*(Supuestos!$E$8*(Supuestos!$E$19*Supuestos!$E$25+Supuestos!$E$20*Supuestos!$E$26+Supuestos!$E$21*Supuestos!$E$27+Supuestos!$E$22*Supuestos!$E$28)/12*$B$19+$B$21)))) | C31: =IF((Supuestos!$E$9+Supuestos!$E$8*$A31)*(1-Supuestos!$E$12*Supuestos!$E$13)*(1-Supuestos!$E$14)-(Supuestos!$E$24*$B$19+C$30*(Supuestos!$E$8*(Supuestos!$E$19*Supuestos!$E$25+Supuestos!$E$20*Supuestos!$E$26+Supuestos!$E$21*Supuestos!$E$27+Supuestos!$E$22*Supuestos!$E$28)/12*$B$19+$B$21))<=0,"Pierde",$B$23/((Supuestos!$E$9+Supuestos!$E$8*$A31)*(1-Supuestos!$E$12*Supuestos!$E$13)*(1-Supuestos!$E$14)-(Supuestos!$E$24*$B$19+C$30*(Supuestos!$E$8*(Supuestos!$E$19*Supuestos!$E$25+Supuestos!$E$20*Supuestos!$E$26+Supuestos!$E$21*Supuestos!$E$27+Supuestos!$E$22*Supuestos!$E$28)/12*$B$19+$B$21)))) | D31: =IF((Supuestos!$E$9+Supuestos!$E$8*$A31)*(1-Supuestos!$E$12*Supuestos!$E$13)*(1-Supuestos!$E$14)-(Supuestos!$E$24*$B$19+D$30*(Supuestos!$E$8*(Supuestos!$E$19*Supuestos!$E$25+Supuestos!$E$20*Supuestos!$E$26+Supuestos!$E$21*Supuestos!$E$27+Supuestos!$E$22*Supuestos!$E$28)/12*$B$19+$B$21))<=0,"Pierde",$B$23/((Supuestos!$E$9+Supuestos!$E$8*$A31)*(1-Supuestos!$E$12*Supuestos!$E$13)*(1-Supuestos!$E$14)-(Supuestos!$E$24*$B$19+D$30*(Supuestos!$E$8*(Supuestos!$E$19*Supuestos!$E$25+Supuestos!$E$20*Supuestos!$E$26+Supuestos!$E$21*Supuestos!$E$27+Supuestos!$E$22*Supuestos!$E$28)/12*$B$19+$B$21)))) | E31: =IF((Supuestos!$E$9+Supuestos!$E$8*$A31)*(1-Supuestos!$E$12*Supuestos!$E$13)*(1-Supuestos!$E$14)-(Supuestos!$E$24*$B$19+E$30*(Supuestos!$E$8*(Supuestos!$E$19*Supuestos!$E$25+Supuestos!$E$20*Supuestos!$E$26+Supuestos!$E$21*Supuestos!$E$27+Supuestos!$E$22*Supuestos!$E$28)/12*$B$19+$B$21))<=0,"Pierde",$B$23/((Supuestos!$E$9+Supuestos!$E$8*$A31)*(1-Supuestos!$E$12*Supuestos!$E$13)*(1-Supuestos!$E$14)-(Supuestos!$E$24*$B$19+E$30*(Supuestos!$E$8*(Supuestos!$E$19*Supuestos!$E$25+Supuestos!$E$20*Supuestos!$E$26+Supuestos!$E$21*Supuestos!$E$27+Supuestos!$E$22*Supuestos!$E$28)/12*$B$19+$B$21)))) | F31: =IF((Supuestos!$E$9+Supuestos!$E$8*$A31)*(1-Supuestos!$E$12*Supuestos!$E$13)*(1-Supuestos!$E$14)-(Supuestos!$E$24*$B$19+F$30*(Supuestos!$E$8*(Supuestos!$E$19*Supuestos!$E$25+Supuestos!$E$20*Supuestos!$E$26+Supuestos!$E$21*Supuestos!$E$27+Supuestos!$E$22*Supuestos!$E$28)/12*$B$19+$B$21))<=0,"Pierde",$B$23/((Supuestos!$E$9+Supuestos!$E$8*$A31)*(1-Supuestos!$E$12*Supuestos!$E$13)*(1-Supuestos!$E$14)-(Supuestos!$E$24*$B$19+F$30*(Supuestos!$E$8*(Supuestos!$E$19*Supuestos!$E$25+Supuestos!$E$20*Supuestos!$E$26+Supuestos!$E$21*Supuestos!$E$27+Supuestos!$E$22*Supuestos!$E$28)/12*$B$19+$B$21))))
A32: 12 | B32: =IF((Supuestos!$E$9+Supuestos!$E$8*$A32)*(1-Supuestos!$E$12*Supuestos!$E$13)*(1-Supuestos!$E$14)-(Supuestos!$E$24*$B$19+B$30*(Supuestos!$E$8*(Supuestos!$E$19*Supuestos!$E$25+Supuestos!$E$20*Supuestos!$E$26+Supuestos!$E$21*Supuestos!$E$27+Supuestos!$E$22*Supuestos!$E$28)/12*$B$19+$B$21))<=0,"Pierde",$B$23/((Supuestos!$E$9+Supuestos!$E$8*$A32)*(1-Supuestos!$E$12*Supuestos!$E$13)*(1-Supuestos!$E$14)-(Supuestos!$E$24*$B$19+B$30*(Supuestos!$E$8*(Supuestos!$E$19*Supuestos!$E$25+Supuestos!$E$20*Supuestos!$E$26+Supuestos!$E$21*Supuestos!$E$27+Supuestos!$E$22*Supuestos!$E$28)/12*$B$19+$B$21)))) | C32: =IF((Supuestos!$E$9+Supuestos!$E$8*$A32)*(1-Supuestos!$E$12*Supuestos!$E$13)*(1-Supuestos!$E$14)-(Supuestos!$E$24*$B$19+C$30*(Supuestos!$E$8*(Supuestos!$E$19*Supuestos!$E$25+Supuestos!$E$20*Supuestos!$E$26+Supuestos!$E$21*Supuestos!$E$27+Supuestos!$E$22*Supuestos!$E$28)/12*$B$19+$B$21))<=0,"Pierde",$B$23/((Supuestos!$E$9+Supuestos!$E$8*$A32)*(1-Supuestos!$E$12*Supuestos!$E$13)*(1-Supuestos!$E$14)-(Supuestos!$E$24*$B$19+C$30*(Supuestos!$E$8*(Supuestos!$E$19*Supuestos!$E$25+Supuestos!$E$20*Supuestos!$E$26+Supuestos!$E$21*Supuestos!$E$27+Supuestos!$E$22*Supuestos!$E$28)/12*$B$19+$B$21)))) | D32: =IF((Supuestos!$E$9+Supuestos!$E$8*$A32)*(1-Supuestos!$E$12*Supuestos!$E$13)*(1-Supuestos!$E$14)-(Supuestos!$E$24*$B$19+D$30*(Supuestos!$E$8*(Supuestos!$E$19*Supuestos!$E$25+Supuestos!$E$20*Supuestos!$E$26+Supuestos!$E$21*Supuestos!$E$27+Supuestos!$E$22*Supuestos!$E$28)/12*$B$19+$B$21))<=0,"Pierde",$B$23/((Supuestos!$E$9+Supuestos!$E$8*$A32)*(1-Supuestos!$E$12*Supuestos!$E$13)*(1-Supuestos!$E$14)-(Supuestos!$E$24*$B$19+D$30*(Supuestos!$E$8*(Supuestos!$E$19*Supuestos!$E$25+Supuestos!$E$20*Supuestos!$E$26+Supuestos!$E$21*Supuestos!$E$27+Supuestos!$E$22*Supuestos!$E$28)/12*$B$19+$B$21)))) | E32: =IF((Supuestos!$E$9+Supuestos!$E$8*$A32)*(1-Supuestos!$E$12*Supuestos!$E$13)*(1-Supuestos!$E$14)-(Supuestos!$E$24*$B$19+E$30*(Supuestos!$E$8*(Supuestos!$E$19*Supuestos!$E$25+Supuestos!$E$20*Supuestos!$E$26+Supuestos!$E$21*Supuestos!$E$27+Supuestos!$E$22*Supuestos!$E$28)/12*$B$19+$B$21))<=0,"Pierde",$B$23/((Supuestos!$E$9+Supuestos!$E$8*$A32)*(1-Supuestos!$E$12*Supuestos!$E$13)*(1-Supuestos!$E$14)-(Supuestos!$E$24*$B$19+E$30*(Supuestos!$E$8*(Supuestos!$E$19*Supuestos!$E$25+Supuestos!$E$20*Supuestos!$E$26+Supuestos!$E$21*Supuestos!$E$27+Supuestos!$E$22*Supuestos!$E$28)/12*$B$19+$B$21)))) | F32: =IF((Supuestos!$E$9+Supuestos!$E$8*$A32)*(1-Supuestos!$E$12*Supuestos!$E$13)*(1-Supuestos!$E$14)-(Supuestos!$E$24*$B$19+F$30*(Supuestos!$E$8*(Supuestos!$E$19*Supuestos!$E$25+Supuestos!$E$20*Supuestos!$E$26+Supuestos!$E$21*Supuestos!$E$27+Supuestos!$E$22*Supuestos!$E$28)/12*$B$19+$B$21))<=0,"Pierde",$B$23/((Supuestos!$E$9+Supuestos!$E$8*$A32)*(1-Supuestos!$E$12*Supuestos!$E$13)*(1-Supuestos!$E$14)-(Supuestos!$E$24*$B$19+F$30*(Supuestos!$E$8*(Supuestos!$E$19*Supuestos!$E$25+Supuestos!$E$20*Supuestos!$E$26+Supuestos!$E$21*Supuestos!$E$27+Supuestos!$E$22*Supuestos!$E$28)/12*$B$19+$B$21))))
A33: 15 | B33: =IF((Supuestos!$E$9+Supuestos!$E$8*$A33)*(1-Supuestos!$E$12*Supuestos!$E$13)*(1-Supuestos!$E$14)-(Supuestos!$E$24*$B$19+B$30*(Supuestos!$E$8*(Supuestos!$E$19*Supuestos!$E$25+Supuestos!$E$20*Supuestos!$E$26+Supuestos!$E$21*Supuestos!$E$27+Supuestos!$E$22*Supuestos!$E$28)/12*$B$19+$B$21))<=0,"Pierde",$B$23/((Supuestos!$E$9+Supuestos!$E$8*$A33)*(1-Supuestos!$E$12*Supuestos!$E$13)*(1-Supuestos!$E$14)-(Supuestos!$E$24*$B$19+B$30*(Supuestos!$E$8*(Supuestos!$E$19*Supuestos!$E$25+Supuestos!$E$20*Supuestos!$E$26+Supuestos!$E$21*Supuestos!$E$27+Supuestos!$E$22*Supuestos!$E$28)/12*$B$19+$B$21)))) | C33: =IF((Supuestos!$E$9+Supuestos!$E$8*$A33)*(1-Supuestos!$E$12*Supuestos!$E$13)*(1-Supuestos!$E$14)-(Supuestos!$E$24*$B$19+C$30*(Supuestos!$E$8*(Supuestos!$E$19*Supuestos!$E$25+Supuestos!$E$20*Supuestos!$E$26+Supuestos!$E$21*Supuestos!$E$27+Supuestos!$E$22*Supuestos!$E$28)/12*$B$19+$B$21))<=0,"Pierde",$B$23/((Supuestos!$E$9+Supuestos!$E$8*$A33)*(1-Supuestos!$E$12*Supuestos!$E$13)*(1-Supuestos!$E$14)-(Supuestos!$E$24*$B$19+C$30*(Supuestos!$E$8*(Supuestos!$E$19*Supuestos!$E$25+Supuestos!$E$20*Supuestos!$E$26+Supuestos!$E$21*Supuestos!$E$27+Supuestos!$E$22*Supuestos!$E$28)/12*$B$19+$B$21)))) | D33: =IF((Supuestos!$E$9+Supuestos!$E$8*$A33)*(1-Supuestos!$E$12*Supuestos!$E$13)*(1-Supuestos!$E$14)-(Supuestos!$E$24*$B$19+D$30*(Supuestos!$E$8*(Supuestos!$E$19*Supuestos!$E$25+Supuestos!$E$20*Supuestos!$E$26+Supuestos!$E$21*Supuestos!$E$27+Supuestos!$E$22*Supuestos!$E$28)/12*$B$19+$B$21))<=0,"Pierde",$B$23/((Supuestos!$E$9+Supuestos!$E$8*$A33)*(1-Supuestos!$E$12*Supuestos!$E$13)*(1-Supuestos!$E$14)-(Supuestos!$E$24*$B$19+D$30*(Supuestos!$E$8*(Supuestos!$E$19*Supuestos!$E$25+Supuestos!$E$20*Supuestos!$E$26+Supuestos!$E$21*Supuestos!$E$27+Supuestos!$E$22*Supuestos!$E$28)/12*$B$19+$B$21)))) | E33: =IF((Supuestos!$E$9+Supuestos!$E$8*$A33)*(1-Supuestos!$E$12*Supuestos!$E$13)*(1-Supuestos!$E$14)-(Supuestos!$E$24*$B$19+E$30*(Supuestos!$E$8*(Supuestos!$E$19*Supuestos!$E$25+Supuestos!$E$20*Supuestos!$E$26+Supuestos!$E$21*Supuestos!$E$27+Supuestos!$E$22*Supuestos!$E$28)/12*$B$19+$B$21))<=0,"Pierde",$B$23/((Supuestos!$E$9+Supuestos!$E$8*$A33)*(1-Supuestos!$E$12*Supuestos!$E$13)*(1-Supuestos!$E$14)-(Supuestos!$E$24*$B$19+E$30*(Supuestos!$E$8*(Supuestos!$E$19*Supuestos!$E$25+Supuestos!$E$20*Supuestos!$E$26+Supuestos!$E$21*Supuestos!$E$27+Supuestos!$E$22*Supuestos!$E$28)/12*$B$19+$B$21)))) | F33: =IF((Supuestos!$E$9+Supuestos!$E$8*$A33)*(1-Supuestos!$E$12*Supuestos!$E$13)*(1-Supuestos!$E$14)-(Supuestos!$E$24*$B$19+F$30*(Supuestos!$E$8*(Supuestos!$E$19*Supuestos!$E$25+Supuestos!$E$20*Supuestos!$E$26+Supuestos!$E$21*Supuestos!$E$27+Supuestos!$E$22*Supuestos!$E$28)/12*$B$19+$B$21))<=0,"Pierde",$B$23/((Supuestos!$E$9+Supuestos!$E$8*$A33)*(1-Supuestos!$E$12*Supuestos!$E$13)*(1-Supuestos!$E$14)-(Supuestos!$E$24*$B$19+F$30*(Supuestos!$E$8*(Supuestos!$E$19*Supuestos!$E$25+Supuestos!$E$20*Supuestos!$E$26+Supuestos!$E$21*Supuestos!$E$27+Supuestos!$E$22*Supuestos!$E$28)/12*$B$19+$B$21))))
A34: 18 | B34: =IF((Supuestos!$E$9+Supuestos!$E$8*$A34)*(1-Supuestos!$E$12*Supuestos!$E$13)*(1-Supuestos!$E$14)-(Supuestos!$E$24*$B$19+B$30*(Supuestos!$E$8*(Supuestos!$E$19*Supuestos!$E$25+Supuestos!$E$20*Supuestos!$E$26+Supuestos!$E$21*Supuestos!$E$27+Supuestos!$E$22*Supuestos!$E$28)/12*$B$19+$B$21))<=0,"Pierde",$B$23/((Supuestos!$E$9+Supuestos!$E$8*$A34)*(1-Supuestos!$E$12*Supuestos!$E$13)*(1-Supuestos!$E$14)-(Supuestos!$E$24*$B$19+B$30*(Supuestos!$E$8*(Supuestos!$E$19*Supuestos!$E$25+Supuestos!$E$20*Supuestos!$E$26+Supuestos!$E$21*Supuestos!$E$27+Supuestos!$E$22*Supuestos!$E$28)/12*$B$19+$B$21)))) | C34: =IF((Supuestos!$E$9+Supuestos!$E$8*$A34)*(1-Supuestos!$E$12*Supuestos!$E$13)*(1-Supuestos!$E$14)-(Supuestos!$E$24*$B$19+C$30*(Supuestos!$E$8*(Supuestos!$E$19*Supuestos!$E$25+Supuestos!$E$20*Supuestos!$E$26+Supuestos!$E$21*Supuestos!$E$27+Supuestos!$E$22*Supuestos!$E$28)/12*$B$19+$B$21))<=0,"Pierde",$B$23/((Supuestos!$E$9+Supuestos!$E$8*$A34)*(1-Supuestos!$E$12*Supuestos!$E$13)*(1-Supuestos!$E$14)-(Supuestos!$E$24*$B$19+C$30*(Supuestos!$E$8*(Supuestos!$E$19*Supuestos!$E$25+Supuestos!$E$20*Supuestos!$E$26+Supuestos!$E$21*Supuestos!$E$27+Supuestos!$E$22*Supuestos!$E$28)/12*$B$19+$B$21)))) | D34: =IF((Supuestos!$E$9+Supuestos!$E$8*$A34)*(1-Supuestos!$E$12*Supuestos!$E$13)*(1-Supuestos!$E$14)-(Supuestos!$E$24*$B$19+D$30*(Supuestos!$E$8*(Supuestos!$E$19*Supuestos!$E$25+Supuestos!$E$20*Supuestos!$E$26+Supuestos!$E$21*Supuestos!$E$27+Supuestos!$E$22*Supuestos!$E$28)/12*$B$19+$B$21))<=0,"Pierde",$B$23/((Supuestos!$E$9+Supuestos!$E$8*$A34)*(1-Supuestos!$E$12*Supuestos!$E$13)*(1-Supuestos!$E$14)-(Supuestos!$E$24*$B$19+D$30*(Supuestos!$E$8*(Supuestos!$E$19*Supuestos!$E$25+Supuestos!$E$20*Supuestos!$E$26+Supuestos!$E$21*Supuestos!$E$27+Supuestos!$E$22*Supuestos!$E$28)/12*$B$19+$B$21)))) | E34: =IF((Supuestos!$E$9+Supuestos!$E$8*$A34)*(1-Supuestos!$E$12*Supuestos!$E$13)*(1-Supuestos!$E$14)-(Supuestos!$E$24*$B$19+E$30*(Supuestos!$E$8*(Supuestos!$E$19*Supuestos!$E$25+Supuestos!$E$20*Supuestos!$E$26+Supuestos!$E$21*Supuestos!$E$27+Supuestos!$E$22*Supuestos!$E$28)/12*$B$19+$B$21))<=0,"Pierde",$B$23/((Supuestos!$E$9+Supuestos!$E$8*$A34)*(1-Supuestos!$E$12*Supuestos!$E$13)*(1-Supuestos!$E$14)-(Supuestos!$E$24*$B$19+E$30*(Supuestos!$E$8*(Supuestos!$E$19*Supuestos!$E$25+Supuestos!$E$20*Supuestos!$E$26+Supuestos!$E$21*Supuestos!$E$27+Supuestos!$E$22*Supuestos!$E$28)/12*$B$19+$B$21)))) | F34: =IF((Supuestos!$E$9+Supuestos!$E$8*$A34)*(1-Supuestos!$E$12*Supuestos!$E$13)*(1-Supuestos!$E$14)-(Supuestos!$E$24*$B$19+F$30*(Supuestos!$E$8*(Supuestos!$E$19*Supuestos!$E$25+Supuestos!$E$20*Supuestos!$E$26+Supuestos!$E$21*Supuestos!$E$27+Supuestos!$E$22*Supuestos!$E$28)/12*$B$19+$B$21))<=0,"Pierde",$B$23/((Supuestos!$E$9+Supuestos!$E$8*$A34)*(1-Supuestos!$E$12*Supuestos!$E$13)*(1-Supuestos!$E$14)-(Supuestos!$E$24*$B$19+F$30*(Supuestos!$E$8*(Supuestos!$E$19*Supuestos!$E$25+Supuestos!$E$20*Supuestos!$E$26+Supuestos!$E$21*Supuestos!$E$27+Supuestos!$E$22*Supuestos!$E$28)/12*$B$19+$B$21))))
A35: 20 | B35: =IF((Supuestos!$E$9+Supuestos!$E$8*$A35)*(1-Supuestos!$E$12*Supuestos!$E$13)*(1-Supuestos!$E$14)-(Supuestos!$E$24*$B$19+B$30*(Supuestos!$E$8*(Supuestos!$E$19*Supuestos!$E$25+Supuestos!$E$20*Supuestos!$E$26+Supuestos!$E$21*Supuestos!$E$27+Supuestos!$E$22*Supuestos!$E$28)/12*$B$19+$B$21))<=0,"Pierde",$B$23/((Supuestos!$E$9+Supuestos!$E$8*$A35)*(1-Supuestos!$E$12*Supuestos!$E$13)*(1-Supuestos!$E$14)-(Supuestos!$E$24*$B$19+B$30*(Supuestos!$E$8*(Supuestos!$E$19*Supuestos!$E$25+Supuestos!$E$20*Supuestos!$E$26+Supuestos!$E$21*Supuestos!$E$27+Supuestos!$E$22*Supuestos!$E$28)/12*$B$19+$B$21)))) | C35: =IF((Supuestos!$E$9+Supuestos!$E$8*$A35)*(1-Supuestos!$E$12*Supuestos!$E$13)*(1-Supuestos!$E$14)-(Supuestos!$E$24*$B$19+C$30*(Supuestos!$E$8*(Supuestos!$E$19*Supuestos!$E$25+Supuestos!$E$20*Supuestos!$E$26+Supuestos!$E$21*Supuestos!$E$27+Supuestos!$E$22*Supuestos!$E$28)/12*$B$19+$B$21))<=0,"Pierde",$B$23/((Supuestos!$E$9+Supuestos!$E$8*$A35)*(1-Supuestos!$E$12*Supuestos!$E$13)*(1-Supuestos!$E$14)-(Supuestos!$E$24*$B$19+C$30*(Supuestos!$E$8*(Supuestos!$E$19*Supuestos!$E$25+Supuestos!$E$20*Supuestos!$E$26+Supuestos!$E$21*Supuestos!$E$27+Supuestos!$E$22*Supuestos!$E$28)/12*$B$19+$B$21)))) | D35: =IF((Supuestos!$E$9+Supuestos!$E$8*$A35)*(1-Supuestos!$E$12*Supuestos!$E$13)*(1-Supuestos!$E$14)-(Supuestos!$E$24*$B$19+D$30*(Supuestos!$E$8*(Supuestos!$E$19*Supuestos!$E$25+Supuestos!$E$20*Supuestos!$E$26+Supuestos!$E$21*Supuestos!$E$27+Supuestos!$E$22*Supuestos!$E$28)/12*$B$19+$B$21))<=0,"Pierde",$B$23/((Supuestos!$E$9+Supuestos!$E$8*$A35)*(1-Supuestos!$E$12*Supuestos!$E$13)*(1-Supuestos!$E$14)-(Supuestos!$E$24*$B$19+D$30*(Supuestos!$E$8*(Supuestos!$E$19*Supuestos!$E$25+Supuestos!$E$20*Supuestos!$E$26+Supuestos!$E$21*Supuestos!$E$27+Supuestos!$E$22*Supuestos!$E$28)/12*$B$19+$B$21)))) | E35: =IF((Supuestos!$E$9+Supuestos!$E$8*$A35)*(1-Supuestos!$E$12*Supuestos!$E$13)*(1-Supuestos!$E$14)-(Supuestos!$E$24*$B$19+E$30*(Supuestos!$E$8*(Supuestos!$E$19*Supuestos!$E$25+Supuestos!$E$20*Supuestos!$E$26+Supuestos!$E$21*Supuestos!$E$27+Supuestos!$E$22*Supuestos!$E$28)/12*$B$19+$B$21))<=0,"Pierde",$B$23/((Supuestos!$E$9+Supuestos!$E$8*$A35)*(1-Supuestos!$E$12*Supuestos!$E$13)*(1-Supuestos!$E$14)-(Supuestos!$E$24*$B$19+E$30*(Supuestos!$E$8*(Supuestos!$E$19*Supuestos!$E$25+Supuestos!$E$20*Supuestos!$E$26+Supuestos!$E$21*Supuestos!$E$27+Supuestos!$E$22*Supuestos!$E$28)/12*$B$19+$B$21)))) | F35: =IF((Supuestos!$E$9+Supuestos!$E$8*$A35)*(1-Supuestos!$E$12*Supuestos!$E$13)*(1-Supuestos!$E$14)-(Supuestos!$E$24*$B$19+F$30*(Supuestos!$E$8*(Supuestos!$E$19*Supuestos!$E$25+Supuestos!$E$20*Supuestos!$E$26+Supuestos!$E$21*Supuestos!$E$27+Supuestos!$E$22*Supuestos!$E$28)/12*$B$19+$B$21))<=0,"Pierde",$B$23/((Supuestos!$E$9+Supuestos!$E$8*$A35)*(1-Supuestos!$E$12*Supuestos!$E$13)*(1-Supuestos!$E$14)-(Supuestos!$E$24*$B$19+F$30*(Supuestos!$E$8*(Supuestos!$E$19*Supuestos!$E$25+Supuestos!$E$20*Supuestos!$E$26+Supuestos!$E$21*Supuestos!$E$27+Supuestos!$E$22*Supuestos!$E$28)/12*$B$19+$B$21))))
A36: 25 | B36: =IF((Supuestos!$E$9+Supuestos!$E$8*$A36)*(1-Supuestos!$E$12*Supuestos!$E$13)*(1-Supuestos!$E$14)-(Supuestos!$E$24*$B$19+B$30*(Supuestos!$E$8*(Supuestos!$E$19*Supuestos!$E$25+Supuestos!$E$20*Supuestos!$E$26+Supuestos!$E$21*Supuestos!$E$27+Supuestos!$E$22*Supuestos!$E$28)/12*$B$19+$B$21))<=0,"Pierde",$B$23/((Supuestos!$E$9+Supuestos!$E$8*$A36)*(1-Supuestos!$E$12*Supuestos!$E$13)*(1-Supuestos!$E$14)-(Supuestos!$E$24*$B$19+B$30*(Supuestos!$E$8*(Supuestos!$E$19*Supuestos!$E$25+Supuestos!$E$20*Supuestos!$E$26+Supuestos!$E$21*Supuestos!$E$27+Supuestos!$E$22*Supuestos!$E$28)/12*$B$19+$B$21)))) | C36: =IF((Supuestos!$E$9+Supuestos!$E$8*$A36)*(1-Supuestos!$E$12*Supuestos!$E$13)*(1-Supuestos!$E$14)-(Supuestos!$E$24*$B$19+C$30*(Supuestos!$E$8*(Supuestos!$E$19*Supuestos!$E$25+Supuestos!$E$20*Supuestos!$E$26+Supuestos!$E$21*Supuestos!$E$27+Supuestos!$E$22*Supuestos!$E$28)/12*$B$19+$B$21))<=0,"Pierde",$B$23/((Supuestos!$E$9+Supuestos!$E$8*$A36)*(1-Supuestos!$E$12*Supuestos!$E$13)*(1-Supuestos!$E$14)-(Supuestos!$E$24*$B$19+C$30*(Supuestos!$E$8*(Supuestos!$E$19*Supuestos!$E$25+Supuestos!$E$20*Supuestos!$E$26+Supuestos!$E$21*Supuestos!$E$27+Supuestos!$E$22*Supuestos!$E$28)/12*$B$19+$B$21)))) | D36: =IF((Supuestos!$E$9+Supuestos!$E$8*$A36)*(1-Supuestos!$E$12*Supuestos!$E$13)*(1-Supuestos!$E$14)-(Supuestos!$E$24*$B$19+D$30*(Supuestos!$E$8*(Supuestos!$E$19*Supuestos!$E$25+Supuestos!$E$20*Supuestos!$E$26+Supuestos!$E$21*Supuestos!$E$27+Supuestos!$E$22*Supuestos!$E$28)/12*$B$19+$B$21))<=0,"Pierde",$B$23/((Supuestos!$E$9+Supuestos!$E$8*$A36)*(1-Supuestos!$E$12*Supuestos!$E$13)*(1-Supuestos!$E$14)-(Supuestos!$E$24*$B$19+D$30*(Supuestos!$E$8*(Supuestos!$E$19*Supuestos!$E$25+Supuestos!$E$20*Supuestos!$E$26+Supuestos!$E$21*Supuestos!$E$27+Supuestos!$E$22*Supuestos!$E$28)/12*$B$19+$B$21)))) | E36: =IF((Supuestos!$E$9+Supuestos!$E$8*$A36)*(1-Supuestos!$E$12*Supuestos!$E$13)*(1-Supuestos!$E$14)-(Supuestos!$E$24*$B$19+E$30*(Supuestos!$E$8*(Supuestos!$E$19*Supuestos!$E$25+Supuestos!$E$20*Supuestos!$E$26+Supuestos!$E$21*Supuestos!$E$27+Supuestos!$E$22*Supuestos!$E$28)/12*$B$19+$B$21))<=0,"Pierde",$B$23/((Supuestos!$E$9+Supuestos!$E$8*$A36)*(1-Supuestos!$E$12*Supuestos!$E$13)*(1-Supuestos!$E$14)-(Supuestos!$E$24*$B$19+E$30*(Supuestos!$E$8*(Supuestos!$E$19*Supuestos!$E$25+Supuestos!$E$20*Supuestos!$E$26+Supuestos!$E$21*Supuestos!$E$27+Supuestos!$E$22*Supuestos!$E$28)/12*$B$19+$B$21)))) | F36: =IF((Supuestos!$E$9+Supuestos!$E$8*$A36)*(1-Supuestos!$E$12*Supuestos!$E$13)*(1-Supuestos!$E$14)-(Supuestos!$E$24*$B$19+F$30*(Supuestos!$E$8*(Supuestos!$E$19*Supuestos!$E$25+Supuestos!$E$20*Supuestos!$E$26+Supuestos!$E$21*Supuestos!$E$27+Supuestos!$E$22*Supuestos!$E$28)/12*$B$19+$B$21))<=0,"Pierde",$B$23/((Supuestos!$E$9+Supuestos!$E$8*$A36)*(1-Supuestos!$E$12*Supuestos!$E$13)*(1-Supuestos!$E$14)-(Supuestos!$E$24*$B$19+F$30*(Supuestos!$E$8*(Supuestos!$E$19*Supuestos!$E$25+Supuestos!$E$20*Supuestos!$E$26+Supuestos!$E$21*Supuestos!$E$27+Supuestos!$E$22*Supuestos!$E$28)/12*$B$19+$B$21))))
A38: Notas: (1) Fuente de todos los números: supuestos de trabajo, no datos de mercado verificados; reemplácelos con datos reales de las cooperativas (historial de siniestros y multas). (2) El modelo no incluye un evento catastrófico (bus con múltiples víctimas); ver informe. (3) Los cobros anuales adelantados mejoran la caja pero no se modelan como anticipo.

Sheet Supuestos
A1: Plan de Asistencia Legal a Cooperativas de Transporte — Jurix Global
A2: Leyenda: texto AZUL = dato editable · fondo AMARILLO = supuesto clave a validar · NEGRO = fórmula. Montos en USD.
A4: Escenario activo (1 = Pesimista, 2 = Base, 3 = Optimista) | B4: 2
A6: Supuesto | B6: Pesimista | C6: Base | D6: Optimista | E6: ACTIVO | F6: Unidad / nota
A7: Comercial y precio
A8: Buses (socios) por cooperativa | B8: 40 | C8: 40 | D8: 40 | E8: =INDEX(B8:D8,1,$B$4) | F8: unidades; promedio de cooperativa urbana/intracantonal [SUPUESTO]
A9: Cuota base por cooperativa (asesoría societaria permanente) | B9: 300 | C9: 300 | D9: 300 | E9: =INDEX(B9:D9,1,$B$4) | F9: USD/mes por cooperativa
A10: Cuota por bus (asistencia en multas y siniestros) | B10: 15 | C10: 15 | D10: 15 | E10: =INDEX(B10:D10,1,$B$4) | F10: USD/mes por bus
A11: Reajuste anual de precio | B11: 0 | C11: 0.03 | D11: 0.05 | E11: =INDEX(B11:D11,1,$B$4) | F11: aplicado desde el mes 13 y 25
A12: % de cooperativas que pagan anual por adelantado | B12: 0.2 | C12: 0.3 | D12: 0.4 | E12: =INDEX(B12:D12,1,$B$4)
A13: Descuento por pago anual | B13: 0.1 | C13: 0.1 | D13: 0.1 | E13: =INDEX(B13:D13,1,$B$4) | F13: sobre la tarifa
A14: Morosidad / incobrables | B14: 0.15 | C14: 0.08 | D14: 0.05 | E14: =INDEX(B14:D14,1,$B$4) | F14: % de lo facturado que no se cobra
A15: Cooperativas nuevas por mes | B15: 0.25 | C15: 0.5 | D15: 0.75 | E15: =INDEX(B15:D15,1,$B$4) | F15: 0.5 = una cada 2 meses (ciclo de venta largo: aprobación en asamblea)
A16: Pérdida anual de cooperativas (churn) | B16: 0.25 | C16: 0.15 | D16: 0.1 | E16: =INDEX(B16:D16,1,$B$4) | F16: cambios de gerente/consejo, competencia
A17: Máximo de cooperativas atendibles (mercado/zona) | B17: 12 | C17: 15 | D17: 20 | E17: =INDEX(B17:D17,1,$B$4) | F17: techo comercial
A18: Siniestralidad (por bus por año)
A19: Siniestros solo con daños materiales | B19: 0.3 | C19: 0.2 | D19: 0.15 | E19: =INDEX(B19:D19,1,$B$4) | F19: eventos/bus/año [SUPUESTO — reemplazar con datos reales de la cooperativa]
A20: Siniestros con lesionados | B20: 0.08 | C20: 0.06 | D20: 0.04 | E20: =INDEX(B20:D20,1,$B$4) | F20: eventos/bus/año [SUPUESTO]
A21: Siniestros con fallecidos | B21: 0.015 | C21: 0.01 | D21: 0.007 | E21: =INDEX(B21:D21,1,$B$4) | F21: eventos/bus/año [SUPUESTO]
A22: Multas/citaciones que requieren gestión o impugnación | B22: 2 | C22: 1.5 | D22: 1 | E22: =INDEX(B22:D22,1,$B$4) | F22: eventos/bus/año
A23: Horas de abogado por evento
A24: Asesoría societaria/LOEPS por cooperativa | B24: 12 | C24: 10 | D24: 8 | E24: =INDEX(B24:D24,1,$B$4) | F24: horas/mes por cooperativa (asambleas, estatutos, SEPS, ANT)
A25: Siniestro con daños materiales | B25: 10 | C25: 8 | D25: 6 | E25: =INDEX(B25:D25,1,$B$4) | F25: horas (flagrancia, acuerdo, devolución del bus)
A26: Siniestro con lesionados | B26: 35 | C26: 25 | D26: 20 | E26: =INDEX(B26:D26,1,$B$4) | F26: horas
A27: Siniestro con fallecidos | B27: 120 | C27: 80 | D27: 60 | E27: =INDEX(B27:D27,1,$B$4) | F27: horas (todo el proceso; puede ser mucho más)
A28: Multa / citación | B28: 1.5 | C28: 1.5 | D28: 1 | E28: =INDEX(B28:D28,1,$B$4) | F28: horas
A29: Gastos directos por evento (movilización, copias, notaría, trámites)
A30: Siniestro con daños materiales | B30: 40 | C30: 30 | D30: 25 | E30: =INDEX(B30:D30,1,$B$4) | F30: USD/evento
A31: Siniestro con lesionados | B31: 100 | C31: 80 | D31: 60 | E31: =INDEX(B31:D31,1,$B$4) | F31: USD/evento
A32: Siniestro con fallecidos | B32: 300 | C32: 250 | D32: 200 | E32: =INDEX(B32:D32,1,$B$4) | F32: USD/evento (peritajes privados NO incluidos: los paga el cliente)
A33: Equipo y costos fijos mensuales
A34: Costo empresa por abogado dedicado | B34: 1450 | C34: 1400 | D34: 1350 | E34: =INDEX(B34:D34,1,$B$4) | F34: USD/mes: sueldo ~1.050 + aportes IESS, décimos, fondos de reserva y vacaciones [SUPUESTO]
A35: Horas productivas por abogado | B35: 120 | C35: 130 | D35: 140 | E35: =INDEX(B35:D35,1,$B$4) | F35: horas/mes
A36: Abogados dedicados mínimos | B36: 1 | C36: 1 | D36: 1 | E36: =INDEX(B36:D36,1,$B$4) | F36: por cobertura 24/7 se recomienda 2 desde ~6 cooperativas
A37: Tiempo del socio (costo de oportunidad) | B37: 800 | C37: 800 | D37: 800 | E37: =INDEX(B37:D37,1,$B$4) | F37: USD/mes: su tiempo NO es gratis
A38: Asistente administrativa (medio tiempo) | B38: 450 | C38: 450 | D38: 450 | E38: =INDEX(B38:D38,1,$B$4) | F38: USD/mes
A39: Bono de guardia 24/7 (noches y fines de semana) | B39: 300 | C39: 250 | D39: 250 | E39: =INDEX(B39:D39,1,$B$4) | F39: USD/mes
A40: Oficina (proporción) | B40: 250 | C40: 250 | D40: 250 | E40: =INDEX(B40:D40,1,$B$4) | F40: USD/mes
A41: Software, telefonía e internet | B41: 100 | C41: 100 | D41: 100 | E41: =INDEX(B41:D41,1,$B$4) | F41: USD/mes
A42: Movilización fija | B42: 150 | C42: 150 | D42: 150 | E42: =INDEX(B42:D42,1,$B$4) | F42: USD/mes
...

Sheet Flujo 36 meses
A1: Flujo de caja mensual (escenario activo)
A2: Mes →
A3: Concepto | B3: 0 | C3: 1 | D3: 2 | E3: 3 | F3: 4 | G3: 5 | H3: 6 | I3: 7 | J3: 8 | K3: 9 | L3: 10 | M3: 11 | N3: 12 | O3: 13 | P3: 14 | Q3: 15 | R3: 16 | S3: 17 | T3: 18 | U3: 19 | V3: 20 | W3: 21 | X3: 22 | Y3: 23 | Z3: 24 | AA3: 25 | AB3: 26 | AC3: 27 | AD3: 28 | AE3: 29 | AF3: 30 | AG3: 31 | AH3: 32 | AI3: 33 | AJ3: 34 | AK3: 35 | AL3: 36
A4: Cooperativas activas | B4: 0 | C4: =MIN(Supuestos!$E$17,B4*(1-Supuestos!$E$16/12)+Supuestos!$E$15) | D4: =MIN(Supuestos!$E$17,C4*(1-Supuestos!$E$16/12)+Supuestos!$E$15) | E4: =MIN(Supuestos!$E$17,D4*(1-Supuestos!$E$16/12)+Supuestos!$E$15) | F4: =MIN(Supuestos!$E$17,E4*(1-Supuestos!$E$16/12)+Supuestos!$E$15) | G4: =MIN(Supuestos!$E$17,F4*(1-Supuestos!$E$16/12)+Supuestos!$E$15) | H4: =MIN(Supuestos!$E$17,G4*(1-Supuestos!$E$16/12)+Supuestos!$E$15) | I4: =MIN(Supuestos!$E$17,H4*(1-Supuestos!$E$16/12)+Supuestos!$E$15) | J4: =MIN(Supuestos!$E$17,I4*(1-Supuestos!$E$16/12)+Supuestos!$E$15) | ... AL4: =MIN(Supuestos!$E$17,AK4*(1-Supuestos!$E$16/12)+Supuestos!$E$15)
A5: Buses atendidos | B5: 0 | C5: =C4*Supuestos!$E$8 | D5: =D4*Supuestos!$E$8 | E5: =E4*Supuestos!$E$8 | F5: =F4*Supuestos!$E$8 | G5: =G4*Supuestos!$E$8 | H5: =H4*Supuestos!$E$8 | I5: =I4*Supuestos!$E$8 | J5: =J4*Supuestos!$E$8 | ... AL5: =AL4*Supuestos!$E$8
A6: Factor de reajuste de precio | B6: 0 | C6: =(1+Supuestos!$E$11)^INT((C$3-1)/12) | D6: =(1+Supuestos!$E$11)^INT((D$3-1)/12) | E6: =(1+Supuestos!$E$11)^INT((E$3-1)/12) | F6: =(1+Supuestos!$E$11)^INT((F$3-1)/12) | G6: =(1+Supuestos!$E$11)^INT((G$3-1)/12) | H6: =(1+Supuestos!$E$11)^INT((H$3-1)/12) | I6: =(1+Supuestos!$E$11)^INT((I$3-1)/12) | J6: =(1+Supuestos!$E$11)^INT((J$3-1)/12) | ... AL6: =(1+Supuestos!$E$11)^INT((AL$3-1)/12)
A7: Ingreso facturado | B7: 0 | C7: =(C4*Supuestos!$E$9+C5*Supuestos!$E$10)*C6*(1-Supuestos!$E$12*Supuestos!$E$13) | D7: =(D4*Supuestos!$E$9+D5*Supuestos!$E$10)*D6*(1-Supuestos!$E$12*Supuestos!$E$13) | E7: =(E4*Supuestos!$E$9+E5*Supuestos!$E$10)*E6*(1-Supuestos!$E$12*Supuestos!$E$13) | F7: =(F4*Supuestos!$E$9+F5*Supuestos!$E$10)*F6*(1-Supuestos!$E$12*Supuestos!$E$13) | G7: =(G4*Supuestos!$E$9+G5*Supuestos!$E$10)*G6*(1-Supuestos!$E$12*Supuestos!$E$13) | H7: =(H4*Supuestos!$E$9+H5*Supuestos!$E$10)*H6*(1-Supuestos!$E$12*Supuestos!$E$13) | I7: =(I4*Supuestos!$E$9+I5*Supuestos!$E$10)*I6*(1-Supuestos!$E$12*Supuestos!$E$13) | J7: =(J4*Supuestos!$E$9+J5*Supuestos!$E$10)*J6*(1-Supuestos!$E$12*Supuestos!$E$13) | ... AL7: =(AL4*Supuestos!$E$9+AL5*Supuestos!$E$10)*AL6*(1-Supuestos!$E$12*Supuestos!$E$13)
A8: Ingreso cobrado | B8: 0 | C8: =C7*(1-Supuestos!$E$14) | D8: =D7*(1-Supuestos!$E$14) | E8: =E7*(1-Supuestos!$E$14) | F8: =F7*(1-Supuestos!$E$14) | G8: =G7*(1-Supuestos!$E$14) | H8: =H7*(1-Supuestos!$E$14) | I8: =I7*(1-Supuestos!$E$14) | J8: =J7*(1-Supuestos!$E$14) | ... AL8: =AL7*(1-Supuestos!$E$14)
A9: Siniestros materiales | B9: 0 | C9: =C5*Supuestos!$E$19/12 | D9: =D5*Supuestos!$E$19/12 | E9: =E5*Supuestos!$E$19/12 | F9: =F5*Supuestos!$E$19/12 | G9: =G5*Supuestos!$E$19/12 | H9: =H5*Supuestos!$E$19/12 | I9: =I5*Supuestos!$E$19/12 | J9: =J5*Supuestos!$E$19/12 | ... AL9: =AL5*Supuestos!$E$19/12
A10: Siniestros con lesionados | B10: 0 | C10: =C5*Supuestos!$E$20/12 | D10: =D5*Supuestos!$E$20/12 | E10: =E5*Supuestos!$E$20/12 | F10: =F5*Supuestos!$E$20/12 | G10: =G5*Supuestos!$E$20/12 | H10: =H5*Supuestos!$E$20/12 | I10: =I5*Supuestos!$E$20/12 | J10: =J5*Supuestos!$E$20/12 | ... AL10: =AL5*Supuestos!$E$20/12
A11: Siniestros con fallecidos | B11: 0 | C11: =C5*Supuestos!$E$21/12 | D11: =D5*Supuestos!$E$21/12 | E11: =E5*Supuestos!$E$21/12 | F11: =F5*Supuestos!$E$21/12 | G11: =G5*Supuestos!$E$21/12 | H11: =H5*Supuestos!$E$21/12 | I11: =I5*Supuestos!$E$21/12 | J11: =J5*Supuestos!$E$21/12 | ... AL11: =AL5*Supuestos!$E$21/12
A12: Multas gestionadas | B12: 0 | C12: =C5*Supuestos!$E$22/12 | D12: =D5*Supuestos!$E$22/12 | E12: =E5*Supuestos!$E$22/12 | F12: =F5*Supuestos!$E$22/12 | G12: =G5*Supuestos!$E$22/12 | H12: =H5*Supuestos!$E$22/12 | I12: =I5*Supuestos!$E$22/12 | J12: =J5*Supuestos!$E$22/12 | ... AL12: =AL5*Supuestos!$E$22/12
A13: Horas de abogado requeridas | B13: 0 | C13: =C4*Supuestos!$E$24+C9*Supuestos!$E$25+C10*Supuestos!$E$26+C11*Supuestos!$E$27+C12*Supuestos!$E$28 | D13: =D4*Supuestos!$E$24+D9*Supuestos!$E$25+D10*Supuestos!$E$26+D11*Supuestos!$E$27+D12*Supuestos!$E$28 | E13: =E4*Supuestos!$E$24+E9*Supuestos!$E$25+E10*Supuestos!$E$26+E11*Supuestos!$E$27+E12*Supuestos!$E$28 | F13: =F4*Supuestos!$E$24+F9*Supuestos!$E$25+F10*Supuestos!$E$26+F11*Supuestos!$E$27+F12*Supuestos!$E$28 | G13: =G4*Supuestos!$E$24+G9*Supuestos!$E$25+G10*Supuestos!$E$26+G11*Supuestos!$E$27+G12*Supuestos!$E$28 | H13: =H4*Supuestos!$E$24+H9*Supuestos!$E$25+H10*Supuestos!$E$26+H11*Supuestos!$E$27+H12*Supuestos!$E$28 | I13: =I4*Supuestos!$E$24+I9*Supuestos!$E$25+I10*Supuestos!$E$26+I11*Supuestos!$E$27+I12*Supuestos!$E$28 | J13: =J4*Supuestos!$E$24+J9*Supuestos!$E$25+J10*Supuestos!$E$26+J11*Supuestos!$E$27+J12*Supuestos!$E$28 | ... AL13: =AL4*Supuestos!$E$24+AL9*Supuestos!$E$25+AL10*Supuestos!$E$26+AL11*Supuestos!$E$27+AL12*Supuestos!$E$28
A14: Abogados dedicados | B14: 0 | C14: =MAX(Supuestos!$E$36,ROUNDUP(C13/Supuestos!$E$35,0)) | D14: =MAX(Supuestos!$E$36,ROUNDUP(D13/Supuestos!$E$35,0)) | E14: =MAX(Supuestos!$E$36,ROUNDUP(E13/Supuestos!$E$35,0)) | F14: =MAX(Supuestos!$E$36,ROUNDUP(F13/Supuestos!$E$35,0)) | G14: =MAX(Supuestos!$E$36,ROUNDUP(G13/Supuestos!$E$35,0)) | H14: =MAX(Supuestos!$E$36,ROUNDUP(H13/Supuestos!$E$35,0)) | I14: =MAX(Supuestos!$E$36,ROUNDUP(I13/Supuestos!$E$35,0)) | J14: =MAX(Supuestos!$E$36,ROUNDUP(J13/Supuestos!$E$35,0)) | ... AL14: =MAX(Supuestos!$E$36,ROUNDUP(AL13/Supuestos!$E$35,0))
A15: Costo de abogados | B15: 0 | C15: =C14*Supuestos!$E$34 | D15: =D14*Supuestos!$E$34 | E15: =E14*Supuestos!$E$34 | F15: =F14*Supuestos!$E$34 | G15: =G14*Supuestos!$E$34 | H15: =H14*Supuestos!$E$34 | I15: =I14*Supuestos!$E$34 | J15: =J14*Supuestos!$E$34 | ... AL15: =AL14*Supuestos!$E$34
A16: Gastos directos de casos | B16: 0 | C16: =C9*Supuestos!$E$30+C10*Supuestos!$E$31+C11*Supuestos!$E$32 | D16: =D9*Supuestos!$E$30+D10*Supuestos!$E$31+D11*Supuestos!$E$32 | E16: =E9*Supuestos!$E$30+E10*Supuestos!$E$31+E11*Supuestos!$E$32 | F16: =F9*Supuestos!$E$30+F10*Supuestos!$E$31+F11*Supuestos!$E$32 | G16: =G9*Supuestos!$E$30+G10*Supuestos!$E$31+G11*Supuestos!$E$32 | H16: =H9*Supuestos!$E$30+H10*Supuestos!$E$31+H11*Supuestos!$E$32 | I16: =I9*Supuestos!$E$30+I10*Supuestos!$E$31+I11*Supuestos!$E$32 | J16: =J9*Supuestos!$E$30+J10*Supuestos!$E$31+J11*Supuestos!$E$32 | ... AL16: =AL9*Supuestos!$E$30+AL10*Supuestos!$E$31+AL11*Supuestos!$E$32
A17: Costos fijos | B17: 0 | C17: =Supuestos!$E$37+Supuestos!$E$38+Supuestos!$E$39+Supuestos!$E$40+Supuestos!$E$41+Supuestos!$E$42+Supuestos!$E$43+Supuestos!$E$44 | D17: =Supuestos!$E$37+Supuestos!$E$38+Supuestos!$E$39+Supuestos!$E$40+Supuestos!$E$41+Supuestos!$E$42+Supuestos!$E$43+Supuestos!$E$44 | E17: =Supuestos!$E$37+Supuestos!$E$38+Supuestos!$E$39+Supuestos!$E$40+Supuestos!$E$41+Supuestos!$E$42+Supuestos!$E$43+Supuestos!$E$44 | F17: =Supuestos!$E$37+Supuestos!$E$38+Supuestos!$E$39+Supuestos!$E$40+Supuestos!$E$41+Supuestos!$E$42+Supuestos!$E$43+Supuestos!$E$44 | G17: =Supuestos!$E$37+Supuestos!$E$38+Supuestos!$E$39+Supuestos!$E$40+Supuestos!$E$41+Supuestos!$E$42+Supuestos!$E$43+Supuestos!$E$44 | H17: =Supuestos!$E$37+Supuestos!$E$38+Supuestos!$E$39+Supuestos!$E$40+Supuestos!$E$41+Supuestos!$E$42+Supuestos!$E$43+Supuestos!$E$44 | I17: =Supuestos!$E$37+Supuestos!$E$38+Supuestos!$E$39+Supuestos!$E$40+Supuestos!$E$41+Supuestos!$E$42+Supuestos!$E$43+Supuestos!$E$44 | J17: =Supuestos!$E$37+Supuestos!$E$38+Supuestos!$E$39+Supuestos!$E$40+Supuestos!$E$41+Supuestos!$E$42+Supuestos!$E$43+Supuestos!$E$44 | ... AL17: =Supuestos!$E$37+Supuestos!$E$38+Supuestos!$E$39+Supuestos!$E$40+Supuestos!$E$41+Supuestos!$E$42+Supuestos!$E$43+Supuestos!$E$44
A18: Resultado operativo (antes de impuestos) | B18: 0 | C18: =C8-C15-C16-C17 | D18: =D8-D15-D16-D17 | E18: =E8-E15-E16-E17 | F18: =F8-F15-F16-F17 | G18: =G8-G15-G16-G17 | H18: =H8-H15-H16-H17 | I18: =I8-I15-I16-I17 | J18: =J8-J15-J16-J17 | ... AL18: =AL8-AL15-AL16-AL17
A19: Impuestos y participación | B19: 0 | C19: =MAX(0,C18)*Supuestos!$E$47 | D19: =MAX(0,D18)*Supuestos!$E$47 | E19: =MAX(0,E18)*Supuestos!$E$47 | F19: =MAX(0,F18)*Supuestos!$E$47 | G19: =MAX(0,G18)*Supuestos!$E$47 | H19: =MAX(0,H18)*Supuestos!$E$47 | I19: =MAX(0,I18)*Supuestos!$E$47 | J19: =MAX(0,J18)*Supuestos!$E$47 | ... AL19: =MAX(0,AL18)*Supuestos!$E$47
A20: Flujo de caja neto | B20: =-Supuestos!$E$46 | C20: =C18-C19 | D20: =D18-D19 | E20: =E18-E19 | F20: =F18-F19 | G20: =G18-G19 | H20: =H18-H19 | I20: =I18-I19 | J20: =J18-J19 | ... AL20: =AL18-AL19
A21: Flujo acumulado | B21: =B20 | C21: =B21+C20 | D21: =C21+D20 | E21: =D21+E20 | F21: =E21+F20 | G21: =F21+G20 | H21: =G21+H20 | I21: =H21+I20 | J21: =I21+J20 | ... AL21: =AK21+AL20
A22: Marca de recupero | B22: ="" | C22: =IF(AND(C21>=0,B21<0),C$3,"") | D22: =IF(AND(D21>=0,C21<0),D$3,"") | E22: =IF(AND(E21>=0,D21<0),E$3,"") | F22: =IF(AND(F21>=0,E21<0),F$3,"") | G22: =IF(AND(G21>=0,F21<0),G$3,"") | H22: =IF(AND(H21>=0,G21<0),H$3,"") | I22: =IF(AND(I21>=0,H21<0),I$3,"") | J22: =IF(AND(J21>=0,I21<0),J$3,"") | ... AL22: =IF(AND(AL21>=0,AK21<0),AL$3,"")
